<?xml version="1.0"?>
<robot name="planting_robot">
    <!-- Base Link -->
    <link name="base_link">
        <visual>
            <geometry>
                <box size="0.8 0.6 0.2"/>
            </geometry>
            <material name="dark_grey">
                <color rgba="0.2 0.2 0.2 1"/>
            </material>
        </visual>
        <collision>
            <geometry>
                <box size="0.8 0.6 0.2"/>
            </geometry>
        </collision>
        <inertial>
            <mass value="50.0"/>
            <inertia ixx="2.0" ixy="0.0" ixz="0.0" iyy="2.0" iyz="0.0" izz="3.0"/>
        </inertial>
    </link>

    <!-- Wheels -->
    <link name="wheel_front_left">
        <visual>
            <geometry>
                <cylinder length="0.1" radius="0.15"/>
            </geometry>
            <material name="black">
                <color rgba="0.1 0.1 0.1 1"/>
            </material>
        </visual>
        <collision>
            <geometry>
                <cylinder length="0.1" radius="0.15"/>
            </geometry>
        </collision>
        <inertial>
            <mass value="2.0"/>
            <inertia ixx="0.1" ixy="0.0" ixz="0.0" iyy="0.1" iyz="0.0" izz="0.1"/>
        </inertial>
    </link>

    <!-- Telescopic Lift -->
    <link name="lift_base">
        <visual>
            <geometry>
                <cylinder length="0.8" radius="0.1"/>
            </geometry>
            <material name="blue">
                <color rgba="0.0 0.0 0.8 1"/>
            </material>
        </visual>
        <collision>
            <geometry>
                <cylinder length="0.8" radius="0.1"/>
            </geometry>
        </collision>
        <inertial>
            <mass value="5.0"/>
            <inertia ixx="0.1" ixy="0.0" ixz="0.0" iyy="0.1" iyz="0.0" izz="0.05"/>
        </inertial>
    </link>

    <!-- 6-DOF Arm Links -->
    <link name="arm_base">
        <visual>
            <geometry>
                <cylinder length="0.2" radius="0.1"/>
            </geometry>
            <material name="silver">
                <color rgba="0.8 0.8 0.8 1"/>
            </material>
        </visual>
        <collision>
            <geometry>
                <cylinder length="0.2" radius="0.1"/>
            </geometry>
        </collision>
        <inertial>
            <mass value="2.0"/>
            <inertia ixx="0.1" ixy="0.0" ixz="0.0" iyy="0.1" iyz="0.0" izz="0.1"/>
        </inertial>
    </link>

    <!-- End Effector -->
    <link name="end_effector">
        <visual>
            <geometry>
                <box size="0.2 0.15 0.15"/>
            </geometry>
            <material name="green">
                <color rgba="0.0 0.8 0.0 1"/>
            </material>
        </visual>
        <collision>
            <geometry>
                <box size="0.2 0.15 0.15"/>
            </geometry>
        </collision>
        <inertial>
            <mass value="1.5"/>
            <inertia ixx="0.01" ixy="0.0" ixz="0.0" iyy="0.01" iyz="0.0" izz="0.01"/>
        </inertial>
    </link>

    <!-- Joints -->
    <joint name="base_to_wheel_fl" type="continuous">
        <parent link="base_link"/>
        <child link="wheel_front_left"/>
        <origin xyz="0.3 0.35 -0.1" rpy="1.5708 0 0"/>
        <axis xyz="0 0 1"/>
    </joint>

    <joint name="base_to_lift" type="prismatic">
        <parent link="base_link"/>
        <child link="lift_base"/>
        <origin xyz="0 0 0.1"/>
        <axis xyz="0 0 1"/>
        <limit lower="0" upper="0.8" effort="1000" velocity="0.5"/>
    </joint>

    <joint name="lift_to_arm_base" type="revolute">
        <parent link="lift_base"/>
        <child link="arm_base"/>
        <origin xyz="0 0 0.8"/>
        <axis xyz="0 0 1"/>
        <limit lower="-3.14" upper="3.14" effort="100" velocity="1.0"/>
    </joint>

    <joint name="arm_to_end_effector" type="fixed">
        <parent link="arm_base"/>
        <child link="end_effector"/>
        <origin xyz="0 0 0.2"/>
    </joint>

    <!-- Sensors -->
    <link name="camera_link">
        <visual>
            <geometry>
                <box size="0.05 0.05 0.05"/>
            </geometry>
            <material name="black"/>
        </visual>
    </link>

    <joint name="camera_joint" type="fixed">
        <parent link="end_effector"/>
        <child link="camera_link"/>
        <origin xyz="0.1 0 0" rpy="0 0.7854 0"/>
    </joint>

    <!-- Gazebo plugins -->
    <gazebo>
        <plugin name="differential_drive_controller" filename="libgazebo_ros_diff_drive.so">
            <leftJoint>base_to_wheel_fl</leftJoint>
            <rightJoint>base_to_wheel_fr</rightJoint>
            <wheelSeparation>0.7</wheelSeparation>
            <wheelDiameter>0.3</wheelDiameter>
            <robotBaseFrame>base_link</robotBaseFrame>
            <publishWheelTF>true</publishWheelTF>
            <publishWheelJointState>true</publishWheelJointState>
        </plugin>
    </gazebo>

    <gazebo reference="camera_link">
        <sensor type="depth" name="camera">
            <update_rate>20</update_rate>
            <camera>
                <horizontal_fov>1.047198</horizontal_fov>
                <image>
                    <width>640</width>
                    <height>480</height>
                    <format>R8G8B8</format>
                </image>
                <clip>
                    <near>0.05</near>
                    <far>3.0</far>
                </clip>
            </camera>
            <plugin name="camera_controller" filename="libgazebo_ros_camera.so">
                <frame_name>camera_link</frame_name>
            </plugin>
        </sensor>
    </gazebo>
</robot> 